Workbook

Sheet Power Budget
A1: Power Budget
A3: Team Number: | B3: 206
A4: Project Name: | B4: Pet Feeder - Light Sensor Board
A5: Team Member Names: | B5: Justin Gonzalez
A6: Version: | B6: 1.0
A8: A. All Major Components | B8: Component Name | C8: Part Number | D8: Supply Voltage Range | E8: # | F8: Absolute Maximum Current (mA) | G8: Total Current (mA) | H8: Unit
B9: Curiosity Nano board | C9: PIC18F57Q43 Curiosity Nano (DM164150) | D9: 1.8 - 5.5V | E9: 1 | F9: =Calcs!B4 -> 23.819 | G9: =E9*F9 -> 23.819 | H9: mA
B10: Quad op amp (3 buffers + 1 tied off) | C10: MCP6004 | D10: 1.8 - 6V | E10: 1 | F10: =Calcs!B5*Calcs!B6 -> 0.68 | G10: =E10*F10 -> 0.68 | H10: mA
B11: Sensor dividers, buttons, LEDs, J3 lines (aggregate) | C11: Resistive loads (see Calcs tab) | D11: 5V | E11: 1 | F11: =Calcs!B37 -> 8.8342948 | G11: =E11*F11 -> 8.8342948 | H11: mA
A12: B. +5V Power Rail | B12: Component Name | C12: Part Number | D12: Supply Voltage Range | E12: # | F12: Absolute Maximum Current (mA) | G12: Total Current (mA) | H12: Unit
B13: =B9 -> Curiosity Nano board | C13: =C9 -> PIC18F57Q43 Curiosity Nano (DM164150) | D13: =D9 -> 1.8 - 5.5V | E13: =E9 -> 1 | F13: =F9 -> 23.819 | G13: =G9 -> 23.819 | H13: mA
B14: =B10 -> Quad op amp (3 buffers + 1 tied off) | C14: =C10 -> MCP6004 | D14: =D10 -> 1.8 - 6V | E14: =E10 -> 1 | F14: =F10 -> 0.68 | G14: =G10 -> 0.68 | H14: mA
B15: =B11 -> Sensor dividers, buttons, LEDs, J3 lines (aggregate) | C15: =C11 -> Resistive loads (see Calcs tab) | D15: =D11 -> 5V | E15: =E11 -> 1 | F15: =F11 -> 8.8342948 | G15: =G11 -> 8.8342948 | H15: mA
F16: Subtotal | G16: =SUM(G13:G15) -> 33.333295 | H16: mA
F17: Safety Margin | G17: =Calcs!B7 -> 0.25
F18: Total Current Required on +5V Rail | G18: =G16*(1+G17) -> 41.666618 | H18: mA
A20: c1. Regulator or Source Choice | B20: +5V linear regulator | C20: L7805ABV-DG | D20: 7.5 - 35V | E20: 1 | F20: =Calcs!B8 -> 1500 | G20: =E20*F20 -> 1500 | H20: mA
F21: Total Remaining Current Available on +5V Rail | G21: =G20-G18 -> 1458.3334 | H21: mA
A23: D. External Power Source 1 | B23: Component Name | C23: Part Number | D23: Supply Voltage Range | E23: Output Voltage | F23: Absolute Maximum Current (mA) | G23: Total Current (mA) | H23: Unit
A24: Power Source 1 Selection | B24: Plug-in wall supply (5.5 mm barrel) | C24: BestCH 9V 3A (EA10302 repl.) | D24: 120VAC | E24: ="+"&Calcs!B10&"V" -> +9V | F24: =Calcs!B11 -> 3000 | G24: =F24 -> 3000 | H24: mA
A25: Power Rails Connected to External Power Source 1 | B25: +5V regulator (input current from 9V) | C25: L7805ABV-DG | D25: 7.5 - 35V | F25: =G18+Calcs!B9 -> 47.666618 | G25: =F25 -> 47.666618 | H25: mA
F28: Total Remaining Current Available on External Power Source 1 | G28: =G24-SUM(G25:G27) -> 2952.3334 | H28: mA
A30: E. Battery Life | B30: Component Name | C30: Part Number | D30: Supply Voltage Range | F30: Capacity (mAh) | G30: Required By Regulators
B31: Not applicable | C31: Wall supply used | F31: N/A | G31: N/A
F32: Battery Life | G32: N/A

Sheet Calcs
A1: Calculations and Assumptions
A2: Yellow cells with blue text are inputs you can edit. Everything else is a formula.
A3: Inputs
A4: Curiosity Nano supply current (per board) | B4: =B60 -> 23.819 | C4: mA | D4: Built up in the Nano current section below from PIC18F57Q43 datasheet DS40002147 Tables 47-2 and 47-3, scaled to 5 V.
A5: MCP6004 quiescent current, max, per amplifier | B5: 0.17 | C5: mA | D5: Microchip MCP6001/2/4 datasheet parametrics: Iq max 170 uA (typ 100 uA).
A6: MCP6004 amplifiers powered | B6: 4 | D6: Quad package. U1A-C are buffers; U1D is tied off but still powered.
A7: Safety margin | B7: 0.25 | D7: Course requirement: add a 25% safety margin to the current needed to operate the system.
A8: Regulator max output current (L7805AB) | B8: 1500 | C8: mA | D8: ST DS0422 Rev 38 (L78 series): output current up to 1.5 A.
A9: Regulator quiescent current, max (L7805AB) | B9: 6 | C9: mA | D9: ST DS0422 Table 3: Iq 4.3 mA typ, 6 mA max.
A10: Wall supply output voltage | B10: 9 | C10: V | D10: BestCH 9 V 3 A switching adapter (listed as a replacement for the EDAC EA10302), per your listing. Check the label for the exact rating.
A11: Wall supply max current | B11: 3000 | C11: mA | D11: BestCH adapter rated 3.0 A, per your listing.
A12: Regulator output voltage | B12: 5 | C12: V | D12: Fixed 5 V output.
A13: Thermal resistance junction-ambient, TO-220 | B13: 50 | C13: C/W | D13: ST DS0422 Table 2. No heatsink assumed.
A14: Max operating junction temperature (L7805AB) | B14: 125 | C14: C | D14: ST DS0422 Table 1.
A15: Assumed ambient temperature | B15: 40 | C15: C | D15: ASSUMPTION: warm room or enclosure. Change to match where the feeder will live.
A16: Regulator dropout voltage (at 1 A) | B16: 2 | C16: V | D16: ST DS0422 Table 3. Dropout is lower at light load.
A18: Small loads not listed as major components (worst case)
A19: Photoresistor minimum resistance (direct light) | B19: 120 | C19: ohm | D19: Your measurement: 0.12 kohm in direct light. This gives the highest divider current.
A20: Divider resistor (R1, R4, R8) | B20: 10000 | C20: ohm | D20: From schematic.
A21: Current per sensor divider | B21: =B12/(B19+B20)*1000 -> 0.49407115 | C21: mA | D21: 5 V across photoresistor + 10k.
A22: Number of dividers | B22: 3 | D22: R2, R3, R5.
A23: Dividers total | B23: =B21*B22 -> 1.4822134 | C23: mA | D23: All three in direct light at once.
A24: Button pull-up resistor (R6, R7) | B24: 10000 | C24: ohm | D24: From schematic.
A25: Buttons pressed at once | B25: 2 | D25: Worst case: both pressed (pull-up to ground).
A26: Button pull-ups total | B26: =B12/B24*1000*B25 -> 1 | C26: mA
A27: Blue LED forward voltage (D1) | B27: 3 | C27: V | D27: From your project notes (blue LEDs drop about 3 V).
A28: Blue LED series resistor (R10) | B28: 1000 | C28: ohm | D28: From schematic. Change this if you switch to 330 ohm.
A29: Blue LED current | B29: =(B12-B27)/B28*1000 -> 2 | C29: mA
A30: Green LED forward voltage (D2) | B30: 2.1 | C30: V | D30: ASSUMPTION: typical green LED. Replace with the datasheet value for your part.
A31: Green LED series resistor (R11) | B31: 1000 | C31: ohm | D31: From schematic.
A32: Green LED current | B32: =(B12-B30)/B31*1000 -> 2.9 | C32: mA
A33: J3 line series resistor (R9, R13, R15) | B33: 330 | C33: ohm | D33: From schematic.
A34: J3 line pull-down (R12, R16, R17) | B34: 10000 | C34: ohm | D34: From schematic.
A35: J3 lines driven high | B35: 3 | D35: Worst case: primary and both backup lines high. Output pins into the pull-downs.
A36: J3 lines total | B36: =B12/(B33+B34)*1000*B35 -> 1.4520813 | C36: mA | D36: Logic only. Assumes the teammate's board is powered separately and draws nothing from J3.
A37: Total small loads | B37: =B23+B26+B29+B32+B36 -> 8.8342948 | C37: mA
A38: Small loads share of the +5V rail subtotal | B38: =B37/'Power Budget'!G16 -> 0.26502915
A39: Listed in Section A as an aggregate line? | B39: Yes | D39: With the datasheet Nano figure, the 25% margin alone no longer absorbs these loads, so they are included as one line item.
A41: Regulator heat (L7805AB, TO-220)
A42: Regulator output current used | B42: ='Power Budget'!G18 -> 41.666618 | C42: mA | D42: Total current required on the +5 V rail, margin included.
...

Sheet Section C
A1: Section C: Regulator and Power Source Selection
A3: Table 1: +5V rail regulator
A4: Option | B4: Solution | C4: Part Number | D4: Pros | E4: Cons | F4: Selected?
A5: 1 | B5: 5 V linear regulator | C5: L7805ABV-DG | D5: Needs only an input and an output capacitor (C1, C2 on the schematic). Through-hole TO-220. 1.5 A rating against a load of a few tens of mA. 2% output tolerance (A version). Built-in thermal shutdown and short-circuit protection. Quiet output, which suits the ADC readings. Matches the course specification. | E5: Drops the excess voltage as heat, so efficiency is only about 5/9 from a 9 V input. Needs at least about 7.5 V in. Up to 6 mA of its own quiescent current. | F5: Yes
A6: 2 | B6: Switching step-down regulator (discrete) | C6: LM2596T-5.0 | D6: Much higher efficiency, so very little heat. Wider input voltage range. | E6: Needs an inductor, a Schottky diode and larger capacitors, so more parts, cost and board area. Switching noise can disturb the photoresistor ADC readings. Layout is more sensitive. The efficiency gain is worth very little at this load. | F6: No
A7: Rationale | B7: ="Selected: L7805ABV-DG. The +5V rail needs about "&TEXT('Power Budget'!G18,"0")&" mA against the regulator's 1500 mA rating, and it dissipates about "&TEXT(Calcs!B45,"0.00")&" W (junction roughly "&TEXT(Calcs!B47,"0")&_xlfn._LONGTEXT(" C), so no heatsink is needed. At this current the efficiency of a switching regulator is not worth its extra parts, and a linear regulator adds no switching noise to the photoresistor ADC readings. It also matches the course specification of a 9 V jack w","ith a 5 V linear regulator.") -> Selected: L7805ABV-DG. The +5V rail needs about 42 mA against the regulator's 1500 mA rating, and it dissipates about 0.22 W (junction roughly 51 C), so no heatsink is needed. At this current the efficiency of a switching regulator is not worth its extra parts, and a linear regulator adds no switching noise to the photoresistor ADC readings. It also matches the course specification of a 9 V jack with a 5 V linear regulator.
A10: Table 2: External power source
A11: Option | B11: Solution | C11: Part Number | D11: Pros | E11: Cons | F11: Selected?
A12: 1 | B12: 9 V wall adapter | C12: BestCH 9V 3A (EA10302 replacement) | D12: Unlimited runtime. Regulated output. 3 A rating far exceeds what the board draws. Matches the course requirement of a 9 V barrel jack with no USB power. Fits the 5.5 mm barrel jack J1. | E12: Tethered to an outlet and stops working in a power outage. Wrong polarity would damage the board, since there is no reverse-polarity protection. | F12: Yes
A13: 2 | B13: Battery pack | C13: 6 x AA holder, about 9 V | D13: Portable. Keeps working in a power outage. | E13: Finite runtime, so a battery-life calculation would be needed. Voltage sags as the cells discharge and approaches the regulator's minimum input. Batteries must be replaced. | F13: No
A14: Rationale | B14: ="Selected: BestCH 9V 3A wall adapter. After the regulator's input current, the adapter still has about "&TEXT('Power Budget'!G28,"0")&" mA to spare, runtime is unlimited, and it matches the course requirement of a 9 V barrel jack with no USB power. A battery would add a battery-life calculation and its voltage would sag toward the regulator's minimum input." -> Selected: BestCH 9V 3A wall adapter. After the regulator's input current, the adapter still has about 2952 mA to spare, runtime is unlimited, and it matches the course requirement of a 9 V barrel jack with no USB power. A battery would add a battery-life calculation and its voltage would sag toward the regulator's minimum input.
A16: Pros and cons for the alternative options are general characteristics. Check them against the LM2596 and battery pack datasheets before submitting.
